Workbook

Sheet Voorblad
B5: LIFE CYCLE COSTS; Korte Termijn (MJOP) en Lange Termijn (TLP)
B7: In de onderstaande rubrieken 'Algemene gegevens' en 'Beheergegevens' ALLEEN de blauwe teksten invullen/aanpassen
B8: Algemene gegevens
B9: Project | F9: ProRail, Grip op inspecties / Analyse kunstwerken; Opstellen PVE’s
B10: Projectnummer ProRail | F10: Nader in te vullen door ProRail
B11: Naam opsteller - functie | F11: R.H. Alberti - Adviseur civiele constructies & assetmanagement
B12: Vakdiscipline | F12: Civiele techniek, Assetmanagement / instandhouding
B13: Datum MJOP / LT | F13: 43798
B14: Versie - Status | F14: 0.1 - CONCEPT
B16: Beheergegevens kunstwerk (input)
B17: SAP Equipmentnummer | F17: 10592569
B18: PGO-contractgebied | F18: 20
B19: Kunstwerknummer | F19: KW20-123-0050
B20: Kunstwerknaam | F20: Duiker (spoorviaduct) o/d Donge
B21: Geocode | F21: 123
B22: Kilometrering (km) | F22: 15.26
B23: Plaats | F23: Tilburg
B24: Bouwjaar bovenbouw | F24: 1953
B25: Bouwjaar onderbouw | F25: 1862
B26: Bouwjaar constructieve uitbreiding | F26: 1994
B27: Hoofddraagconstructie | F27: Gewapend betonnen plaat
B28: Funderingsconstructie | F28: Metselwerk
B29: Laatste inspectie/opname | F29: 42644
B30: Kunstwerkpaspoort | F30: 43031
B31: Programma van Eisen | F31: 43013
B32: SSK-kostenraming (obv PVE) | F32: 43013 | J32: Prijspijl SSK: | K32: 2017
B33: Bijzonderheden t.a.v. de LCC analyse | F33: Betonnen spoordek (1953) lang 8 m1 + prefab betonnen PV-pad (1994) lang 11 m1 aan zuidzijde
B35: In de onderstaande rubrieken t.b.v. 'invoer' en 'uitkomsten' ALLEEN de Excel-cellen met licht blauwe arcering invullen/aanpassen
B36: Start- en looptijden MJOP / LTP (invoer)
B37: Start looptijd PGO-contract | F37: 2018 | H37: Looptijd MJOP | K37: 10
B38: Einde PGO-contract | F38: =F37+5 -> 2023 | H38: Einde looptijd MJOP | K38: =F37+K37 -> 2028
B39: Voorbereiding nieuw PGO-contract | F39: =F38-2 -> 2021
B41: Start looptijd LTP | F41: 2028 | H41: Looptijd LTP | K41: =F24+100-F41 -> 25
H42: Einde looptijd LTP | K42: =F41+K41 -> 2053
H44: Discontorente | K44: 0.025
B47: Uitkomsten MJOP
B48: Kosten cat. | C48: BHM nr. | D48: ='Berekening MJOP+LTP'!K28 -> Omschrijving | H48: prijspeil SSK als onderdeel van PVE: | J48: 2017 | K48: ='Berekening MJOP+LTP'!W28 -> uitvoering | L48: ='Berekening MJOP+LTP'!T28 -> kosten | M48: ='Berekening MJOP+LTP'!Y28 -> Σ NCW | N48: ='Berekening MJOP+LTP'!AA28 -> TVP duur | O48: Equiv. Jaarlast
B49: ='Berekening MJOP+LTP'!B31 -> 3 | C49: ='Berekening MJOP+LTP'!D31 -> nvt | D49: ='Berekening MJOP+LTP'!O31 -> PGO-contract (service provider) | L49: ='Berekening MJOP+LTP'!T33 -> 6500 | M49: ='Berekening MJOP+LTP'!Y33 -> 6403.571 | O49: ='Berekening MJOP+LTP'!AC33 -> 731.66411
B50: ='Berekening MJOP+LTP'!B35 -> 2 | C50: ='Berekening MJOP+LTP'!D35 -> nvt | D50: ='Berekening MJOP+LTP'!O35 -> advieswerk IB tbv productie plan | L50: ='Berekening MJOP+LTP'!T36 -> 5000 | M50: ='Berekening MJOP+LTP'!Y36 -> 3905.992 | O50: ='Berekening MJOP+LTP'!AC36 -> 446.29382
B51: ='Berekening MJOP+LTP'!B38 -> 2 | C51: ='Berekening MJOP+LTP'!D38 -> 1 | D51: ='Berekening MJOP+LTP'!K38 -> globale beschouwing constructieve veiligheid | K51: 2021 | L51: ='Berekening MJOP+LTP'!T38 -> 5000 | M51: ='Berekening MJOP+LTP'!Y38 -> 4642.9971 | N51: ='Berekening MJOP+LTP'!AA38 -> 0 | O51: ='Berekening MJOP+LTP'!AC38 -> 530.5031
...

Sheet Berekening MJOP+LTP
B1: Kosten | C1: BHM in | D1: BHM | E1: € in PVE | F1: Thema | I1: Maat- | K1: Omschrijving | O1: Uitgangspunten | P1: Aanvullende informatie | Q1: hoev | R1: eenh. | S1: eenh.prijs | T1: kosten | U1: freq | V1: theor.einde | W1: uitvoering | Y1: Σ NCW | Z1: TVP | AA1: TVP duur | AC1: Equiv. | AE1: (Netto Contante) Waarde tabel | EE1: Onderwaterscherm wel/geen waarde
B2: cat. | C2: PVE j/n | D2: nr. | E2: j/n | I2: regel | V2: levensd | AC2: jaarlast
B5: Kostencategorien
B7: Cat. 1 | D7: Beheerkosten tlv ProRail Projecten (assetowner) | K7: Kosten voor de BHM opgenomen in de PVE's en dus ook in het productieplan (PP)
D8: (langcyclisch onderhoud, vervanging e.d.) | K8: Deze zijn ter verantwoording en rekening van ProRail Centraal, afdeling Projecten
D9: Kostenkengetallen zijn op niveau van investeringskosten | K9: Kosten voor de geadviseerde BHM die niet zijn opgenomen in de PVE's maar wel zijn opgenomen in de KW-paspoorten
D10: Factor van niveau BDBK -> INV: | H10: 2.38 | I10: 2.38
B12: Cat. 2 | D12: Beheerkosten tlv ProRail AM (assetmanager) | K12: Deze BHM zijn nodig om het risicoprofiel van het betreffende KW te verlagen
D13: Regio Zuid | K13: Kosten voor de BHM en onderhoud om de functionaliteit van het KW te waarborgen en om degradatie v/h KW te voorkomen
D14: Kostenkengetallen zijn op niveau van bouwkosten
D15: Factor van niveau BDBK -> BK: | H15: 1.77
B17: Cat. 3 | D17: Beheerkosten tlv PGO-contract (service provider) | K17: in model opnemen startjaar (keuzejaar) voor LTP (los van startjaar PGO maar wel jaartal in zelfde kolom)
D18: (kortcyclisch onderhoud) | K18: vervangingskosten opnemen in LTP gekoppeld aan bouwjaar
D19: Kostenkengetallen zijn op niveau van bouwkosten | K19: tbv LTP hoeveelheden uit paspoort overnemen? (bv LxB rijdek) tbv regulier onderhoud en vervanging
D20: Factor van niveau BDBK -> BK: | H20: 1.77 | I20: 1.77
K21: Voor kosten kengetallen vervanging zie: "SO-kengetall_verv_kwn_ProRail Zuid"
B24: Alleen de cellen met licht blauwe arcering invullen/aanpassen
B26: MEERJARENONDERHOUDSPLAN (MJOP)
B28: Kosten | C28: BHM in | D28: BHM | E28: € in PVE | F28: Thema | I28: Maat- | K28: Omschrijving | O28: Uitgangspunten | P28: Aanvullende informatie | Q28: hoev | R28: eenh. | S28: eenh.prijs | T28: kosten | U28: freq | V28: theor.einde | W28: uitvoering | Y28: Σ NCW | Z28: TVP | AA28: TVP duur | AC28: Equiv. | AE28: (Netto Contante) Waarde tabel | EE28: Onderwaterscherm wel/geen waarde
B29: cat. | C29: PVE j/n | D29: nr. | E29: j/n | I29: regel | V29: levensd | AC29: jaarlast
AE30: =Voorblad!F37 -> 2018 | AF30: =AE30+1 -> 2019 | AG30: =AF30+1 -> 2020 | AH30: =AG30+1 -> 2021 | AI30: =AH30+1 -> 2022 | AJ30: =AI30+1 -> 2023 | AK30: =AJ30+1 -> 2024 | AL30: =AK30+1 -> 2025 | AM30: =AL30+1 -> 2026 | ... EB30: =EA30+1 -> 2119 | EF30: =Voorblad!F37 -> 2018 | EG30: =EF30+1 -> 2019 | EH30: =EG30+1 -> 2020 | EI30: =EH30+1 -> 2021 | EJ30: =EI30+1 -> 2022 | EK30: =EJ30+1 -> 2023 | EL30: =EK30+1 -> 2024 | EM30: =EL30+1 -> 2025 | EN30: =EM30+1 -> 2026 | ... IB30: =IA30+1 -> 2118
B31: 3 | C31: nee | D31: nvt | E31: nvt | F31: waarborg functie | I31: FMECA | K31: uitvoeren risicoanalyses tbv PGO-contract (FMECA) | O31: PGO-contract (service provider) | Q31: 1 | R31: post | S31: 1500 | T31: =Q31*S31 -> 1500 | U31: 5 | Y31: =SUM(AE31:EB31) -> 2497.579 | AC31: =$Y31*(Voorblad!$K$44*(1+Voorblad!$K$44)^Voorblad!$K$37)/((1+Voorblad!$K$44)^Voorblad!$K$37-1) -> 285.37029 | AE31: =EF31*($Q31*$S31)/(1+Voorblad!$K$44)^(AE$56-Voorblad!$F$41) -> 0 | AF31: =EG31*($Q31*$S31)/(1+Voorblad!$K$44)^(AF$30-Voorblad!$F$37) -> 0 | AG31: =EH31*($Q31*$S31)/(1+Voorblad!$K$44)^(AG$56-Voorblad!$F$41) -> 0 | AH31: =EI31*($Q31*$S31)/(1+Voorblad!$K$44)^(AH$56-Voorblad!$F$41) -> 0 | AI31: =EJ31*($Q31*$S31)/(1+Voorblad!$K$44)^(AI$56-Voorblad!$F$41) -> 0 | AJ31: =EK31*($Q31*$S31)/(1+Voorblad!$K$44)^(AJ$56-Voorblad!$F$41) -> 1325.7814 | AK31: =EL31*($Q31*$S31)/(1+Voorblad!$K$44)^(AK$56-Voorblad!$F$41) -> 0 | AL31: =EM31*($Q31*$S31)/(1+Voorblad!$K$44)^(AL$56-Voorblad!$F$41) -> 0 | AM31: =EN31*($Q31*$S31)/(1+Voorblad!$K$44)^(AM$56-Voorblad!$F$41) -> 0 | AN31: =EO31*($Q31*$S31)/(1+Voorblad!$K$44)^(AN$56-Voorblad!$F$41) -> 0 | ... EB31: =IC31*($Q31*$S31)/(1+Voorblad!$K$44)^(EB$56-Voorblad!$F$41) -> 0 | EE31: 0 | EF31: =IF(EF$30-Voorblad!$F$37>Voorblad!$K$37,0,IF($U31=0,0,IF($U31<1,1/$U31,IF((EF$30-Voorblad!$F$37)/$U31-SUM($EE31:EE31)=1,1,0)))) -> 0 | EG31: =IF(EG$30-Voorblad!$F$37>Voorblad!$K$37,0,IF($U31=0,0,IF($U31<1,1/$U31,IF((EG$30-Voorblad!$F$37)/$U31-SUM($EE31:EF31)=1,1,0)))) -> 0 | EH31: =IF(EH$30-Voorblad!$F$37>Voorblad!$K$37,0,IF($U31=0,0,IF($U31<1,1/$U31,IF((EH$30-Voorblad!$F$37)/$U31-SUM($EE31:EG31)=1,1,0)))) -> 0 | EI31: =IF(EI$30-Voorblad!$F$37>Voorblad!$K$37,0,IF($U31=0,0,IF($U31<1,1/$U31,IF((EI$30-Voorblad!$F$37)/$U31-SUM($EE31:EH31)=1,1,0)))) -> 0 | EJ31: =IF(EJ$30-Voorblad!$F$37>Voorblad!$K$37,0,IF($U31=0,0,IF($U31<1,1/$U31,IF((EJ$30-Voorblad!$F$37)/$U31-SUM($EE31:EI31)=1,1,0)))) -> 0 | EK31: =IF(EK$30-Voorblad!$F$37>Voorblad!$K$37,0,IF($U31=0,0,IF($U31<1,1/$U31,IF((EK$30-Voorblad!$F$37)/$U31-SUM($EE31:EJ31)=1,1,0)))) -> 1 | EL31: =IF(EL$30-Voorblad!$F$37>Voorblad!$K$37,0,IF($U31=0,0,IF($U31<1,1/$U31,IF((EL$30-Voorblad!$F$37)/$U31-SUM($EE31:EK31)=1,1,0)))) -> 0 | EM31: =IF(EM$30-Voorblad!$F$37>Voorblad!$K$37,0,IF($U31=0,0,IF($U31<1,1/$U31,IF((EM$30-Voorblad!$F$37)/$U31-SUM($EE31:EL31)=1,1,0)))) -> 0 | ... IB31: =IF(IB$30-Voorblad!$F$37>Voorblad!$K$37,0,IF($U31=0,0,IF($U31<1,1/$U31,IF((IB$30-Voorblad!$F$37)/$U31-SUM($EE31:IA31)=1,1,0)))) -> 0
B32: 3 | C32: nee | D32: nvt | E32: nvt | F32: waarborg functie | I32: ko | K32: schoonmaken/klein herstel oppervlak, anti-graffiti | O32: PGO-contract (service provider) | Q32: 1 | R32: post | S32: 5000 | T32: =Q32*S32 -> 5000 | U32: 10 | Y32: =SUM(AE32:EB32) -> 3905.992 | AC32: =$Y32*(Voorblad!$K$44*(1+Voorblad!$K$44)^Voorblad!$K$37)/((1+Voorblad!$K$44)^Voorblad!$K$37-1) -> 446.29382 | AE32: =EF32*($Q32*$S32)/(1+Voorblad!$K$44)^(AE$56-Voorblad!$F$41) -> 0 | AF32: =EG32*($Q32*$S32)/(1+Voorblad!$K$44)^(AF$30-Voorblad!$F$37) -> 0 | AG32: =EH32*($Q32*$S32)/(1+Voorblad!$K$44)^(AG$56-Voorblad!$F$41) -> 0 | AH32: =EI32*($Q32*$S32)/(1+Voorblad!$K$44)^(AH$56-Voorblad!$F$41) -> 0 | AI32: =EJ32*($Q32*$S32)/(1+Voorblad!$K$44)^(AI$56-Voorblad!$F$41) -> 0 | AJ32: =EK32*($Q32*$S32)/(1+Voorblad!$K$44)^(AJ$56-Voorblad!$F$41) -> 0 | AK32: =EL32*($Q32*$S32)/(1+Voorblad!$K$44)^(AK$56-Voorblad!$F$41) -> 0 | AL32: =EM32*($Q32*$S32)/(1+Voorblad!$K$44)^(AL$56-Voorblad!$F$41) -> 0 | AM32: =EN32*($Q32*$S32)/(1+Voorblad!$K$44)^(AM$56-Voorblad!$F$41) -> 0 | AN32: =EO32*($Q32*$S32)/(1+Voorblad!$K$44)^(AN$56-Voorblad!$F$41) -> 0 | ... EB32: =IC32*($Q32*$S32)/(1+Voorblad!$K$44)^(EB$56-Voorblad!$F$41) -> 0 | EE32: 0 | EF32: =IF(EF$30-Voorblad!$F$37>Voorblad!$K$37,0,IF($U32=0,0,IF($U32<1,1/$U32,IF((EF$30-Voorblad!$F$37)/$U32-SUM($EE32:EE32)=1,1,0)))) -> 0 | EG32: =IF(EG$30-Voorblad!$F$37>Voorblad!$K$37,0,IF($U32=0,0,IF($U32<1,1/$U32,IF((EG$30-Voorblad!$F$37)/$U32-SUM($EE32:EF32)=1,1,0)))) -> 0 | EH32: =IF(EH$30-Voorblad!$F$37>Voorblad!$K$37,0,IF($U32=0,0,IF($U32<1,1/$U32,IF((EH$30-Voorblad!$F$37)/$U32-SUM($EE32:EG32)=1,1,0)))) -> 0 | EI32: =IF(EI$30-Voorblad!$F$37>Voorblad!$K$37,0,IF($U32=0,0,IF($U32<1,1/$U32,IF((EI$30-Voorblad!$F$37)/$U32-SUM($EE32:EH32)=1,1,0)))) -> 0 | EJ32: =IF(EJ$30-Voorblad!$F$37>Voorblad!$K$37,0,IF($U32=0,0,IF($U32<1,1/$U32,IF((EJ$30-Voorblad!$F$37)/$U32-SUM($EE32:EI32)=1,1,0)))) -> 0 | EK32: =IF(EK$30-Voorblad!$F$37>Voorblad!$K$37,0,IF($U32=0,0,IF($U32<1,1/$U32,IF((EK$30-Voorblad!$F$37)/$U32-SUM($EE32:EJ32)=1,1,0)))) -> 0 | EL32: =IF(EL$30-Voorblad!$F$37>Voorblad!$K$37,0,IF($U32=0,0,IF($U32<1,1/$U32,IF((EL$30-Voorblad!$F$37)/$U32-SUM($EE32:EK32)=1,1,0)))) -> 0 | EM32: =IF(EM$30-Voorblad!$F$37>Voorblad!$K$37,0,IF($U32=0,0,IF($U32<1,1/$U32,IF((EM$30-Voorblad!$F$37)/$U32-SUM($EE32:EL32)=1,1,0)))) -> 0 | ... IB32: =IF(IB$30-Voorblad!$F$37>Voorblad!$K$37,0,IF($U32=0,0,IF($U32<1,1/$U32,IF((IB$30-Voorblad!$F$37)/$U32-SUM($EE32:IA32)=1,1,0)))) -> 0
B33: totaal PGO-contract (service provider) | T33: =SUM(T31:T32) -> 6500 | Y33: =SUM(Y31:Y32) -> 6403.571 | AC33: =$Y33*(Voorblad!$K$44*(1+Voorblad!$K$44)^Voorblad!$K$37)/((1+Voorblad!$K$44)^Voorblad!$K$37-1) -> 731.66411
B35: 2 | C35: nvt | D35: nvt | E35: nvt | F35: AM tbv PP | I35: advies | K35: advieswerk IB tbv vullen productieplan | O35: advieswerk IB tbv productie plan | Q35: 1 | R35: post | S35: 5000 | T35: =Q35*S35 -> 5000 | U35: 10 | Y35: =SUM(AE35:EB35) -> 3905.992 | AC35: =$Y35*(Voorblad!$K$44*(1+Voorblad!$K$44)^Voorblad!$K$37)/((1+Voorblad!$K$44)^Voorblad!$K$37-1) -> 446.29382 | AE35: =EF35*($Q35*$S35)/(1+Voorblad!$K$44)^(AE$56-Voorblad!$F$41) -> 0 | AF35: =EG35*($Q35*$S35)/(1+Voorblad!$K$44)^(AF$30-Voorblad!$F$37) -> 0 | AG35: =EH35*($Q35*$S35)/(1+Voorblad!$K$44)^(AG$56-Voorblad!$F$41) -> 0 | AH35: =EI35*($Q35*$S35)/(1+Voorblad!$K$44)^(AH$56-Voorblad!$F$41) -> 0 | AI35: =EJ35*($Q35*$S35)/(1+Voorblad!$K$44)^(AI$56-Voorblad!$F$41) -> 0 | AJ35: =EK35*($Q35*$S35)/(1+Voorblad!$K$44)^(AJ$56-Voorblad!$F$41) -> 0 | AK35: =EL35*($Q35*$S35)/(1+Voorblad!$K$44)^(AK$56-Voorblad!$F$41) -> 0 | AL35: =EM35*($Q35*$S35)/(1+Voorblad!$K$44)^(AL$56-Voorblad!$F$41) -> 0 | AM35: =EN35*($Q35*$S35)/(1+Voorblad!$K$44)^(AM$56-Voorblad!$F$41) -> 0 | AN35: =EO35*($Q35*$S35)/(1+Voorblad!$K$44)^(AN$56-Voorblad!$F$41) -> 0 | ... EB35: =IC35*($Q35*$S35)/(1+Voorblad!$K$44)^(EB$56-Voorblad!$F$41) -> 0 | EE35: 0 | EF35: =IF(EF$30-Voorblad!$F$37>Voorblad!$K$37,0,IF($U35=0,0,IF($U35<1,1/$U35,IF((EF$30-Voorblad!$F$37)/$U35-SUM($EE35:EE35)=1,1,0)))) -> 0 | EG35: =IF(EG$30-Voorblad!$F$37>Voorblad!$K$37,0,IF($U35=0,0,IF($U35<1,1/$U35,IF((EG$30-Voorblad!$F$37)/$U35-SUM($EE35:EF35)=1,1,0)))) -> 0 | EH35: =IF(EH$30-Voorblad!$F$37>Voorblad!$K$37,0,IF($U35=0,0,IF($U35<1,1/$U35,IF((EH$30-Voorblad!$F$37)/$U35-SUM($EE35:EG35)=1,1,0)))) -> 0 | EI35: =IF(EI$30-Voorblad!$F$37>Voorblad!$K$37,0,IF($U35=0,0,IF($U35<1,1/$U35,IF((EI$30-Voorblad!$F$37)/$U35-SUM($EE35:EH35)=1,1,0)))) -> 0 | EJ35: =IF(EJ$30-Voorblad!$F$37>Voorblad!$K$37,0,IF($U35=0,0,IF($U35<1,1/$U35,IF((EJ$30-Voorblad!$F$37)/$U35-SUM($EE35:EI35)=1,1,0)))) -> 0 | EK35: =IF(EK$30-Voorblad!$F$37>Voorblad!$K$37,0,IF($U35=0,0,IF($U35<1,1/$U35,IF((EK$30-Voorblad!$F$37)/$U35-SUM($EE35:EJ35)=1,1,0)))) -> 0 | EL35: =IF(EL$30-Voorblad!$F$37>Voorblad!$K$37,0,IF($U35=0,0,IF($U35<1,1/$U35,IF((EL$30-Voorblad!$F$37)/$U35-SUM($EE35:EK35)=1,1,0)))) -> 0 | EM35: =IF(EM$30-Voorblad!$F$37>Voorblad!$K$37,0,IF($U35=0,0,IF($U35<1,1/$U35,IF((EM$30-Voorblad!$F$37)/$U35-SUM($EE35:EL35)=1,1,0)))) -> 0 | ... IB35: =IF(IB$30-Voorblad!$F$37>Voorblad!$K$37,0,IF($U35=0,0,IF($U35<1,1/$U35,IF((IB$30-Voorblad!$F$37)/$U35-SUM($EE35:IA35)=1,1,0)))) -> 0
B36: totaal advieswerk IB | T36: =SUM(T34:T35) -> 5000 | Y36: =SUM(Y34:Y35) -> 3905.992 | AC36: =$Y36*(Voorblad!$K$44*(1+Voorblad!$K$44)^Voorblad!$K$37)/((1+Voorblad!$K$44)^Voorblad!$K$37-1) -> 446.29382
B38: 2 | C38: ja | D38: 1 | E38: nee | F38: verlagen risicoprofiel | I38: no | K38: globale beschouwing constructieve veiligheid | Q38: 1 | R38: post | S38: 5000 | T38: =Q38*S38 -> 5000 | U38: 1 | W38: =Voorblad!K51 -> 2021 | Y38: =SUM(AE38:EB38) -> 4642.9971 | AC38: =$Y38*(Voorblad!$K$44*(1+Voorblad!$K$44)^Voorblad!$K$37)/((1+Voorblad!$K$44)^Voorblad!$K$37-1) -> 530.5031 | AE38: =IF($W38=AE$30,EF38*($Q38*$S38)/(1+Voorblad!$K$44)^(AE$30-Voorblad!$F$37),0) -> 0 | AF38: =IF($W38=AF$30,EG38*($Q38*$S38)/(1+Voorblad!$K$44)^(AF$30-Voorblad!$F$37),0) -> 0 | AG38: =IF($W38=AG$30,EH38*($Q38*$S38)/(1+Voorblad!$K$44)^(AG$30-Voorblad!$F$37),0) -> 0 | AH38: =IF($W38=AH$30,EI38*($Q38*$S38)/(1+Voorblad!$K$44)^(AH$30-Voorblad!$F$37),0) -> 4642.9971 | AI38: =IF($W38=AI$30,EJ38*($Q38*$S38)/(1+Voorblad!$K$44)^(AI$30-Voorblad!$F$37),0) -> 0 | AJ38: =IF($W38=AJ$30,EK38*($Q38*$S38)/(1+Voorblad!$K$44)^(AJ$30-Voorblad!$F$37),0) -> 0 | AK38: =IF($W38=AK$30,EL38*($Q38*$S38)/(1+Voorblad!$K$44)^(AK$30-Voorblad!$F$37),0) -> 0 | AL38: =IF($W38=AL$30,EM38*($Q38*$S38)/(1+Voorblad!$K$44)^(AL$30-Voorblad!$F$37),0) -> 0 | ... EB38: =IF($W38=EB$30,IC38*($Q38*$S38)/(1+Voorblad!$K$44)^(EB$30-Voorblad!$F$37),0) -> 0 | EE38: 0 | EF38: =IF(EF$30-Voorblad!$F$37>Voorblad!$K$37,0,IF($U38=0,0,IF($U38<1,1/$U38,IF((EF$30-Voorblad!$F$37)/$U38-SUM($EE38:EE38)=1,1,0)))) -> 0 | EG38: =IF(EG$30-Voorblad!$F$37>Voorblad!$K$37,0,IF($U38=0,0,IF($U38<1,1/$U38,IF((EG$30-Voorblad!$F$37)/$U38-SUM($EE38:EF38)=1,1,0)))) -> 1 | EH38: =IF(EH$30-Voorblad!$F$37>Voorblad!$K$37,0,IF($U38=0,0,IF($U38<1,1/$U38,IF((EH$30-Voorblad!$F$37)/$U38-SUM($EE38:EG38)=1,1,0)))) -> 1 | EI38: =IF(EI$30-Voorblad!$F$37>Voorblad!$K$37,0,IF($U38=0,0,IF($U38<1,1/$U38,IF((EI$30-Voorblad!$F$37)/$U38-SUM($EE38:EH38)=1,1,0)))) -> 1 | EJ38: =IF(EJ$30-Voorblad!$F$37>Voorblad!$K$37,0,IF($U38=0,0,IF($U38<1,1/$U38,IF((EJ$30-Voorblad!$F$37)/$U38-SUM($EE38:EI38)=1,1,0)))) -> 1 | EK38: =IF(EK$30-Voorblad!$F$37>Voorblad!$K$37,0,IF($U38=0,0,IF($U38<1,1/$U38,IF((EK$30-Voorblad!$F$37)/$U38-SUM($EE38:EJ38)=1,1,0)))) -> 1 | EL38: =IF(EL$30-Voorblad!$F$37>Voorblad!$K$37,0,IF($U38=0,0,IF($U38<1,1/$U38,IF((EL$30-Voorblad!$F$37)/$U38-SUM($EE38:EK38)=1,1,0)))) -> 1 | EM38: =IF(EM$30-Voorblad!$F$37>Voorblad!$K$37,0,IF($U38=0,0,IF($U38<1,1/$U38,IF((EM$30-Voorblad!$F$37)/$U38-SUM($EE38:EL38)=1,1,0)))) -> 1 | ... IB38: =IF(IB$30-Voorblad!$F$37>Voorblad!$K$37,0,IF($U38=0,0,IF($U38<1,1/$U38,IF((IB$30-Voorblad!$F$37)/$U38-SUM($EE38:IA38)=1,1,0)))) -> 0
B39: 2 | C39: ja | D39: 2 | E39: nee | F39: verlagen risicoprofiel | I39: no | K39: uitvoeren nader archiefonderzoek kunstwerk | Q39: 1 | R39: post | S39: 500 | T39: =Q39*S39 -> 500 | U39: 1 | W39: =Voorblad!K52 -> 2020 | Y39: =SUM(AE39:EB39) -> 475.9072 | AC39: =$Y39*(Voorblad!$K$44*(1+Voorblad!$K$44)^Voorblad!$K$37)/((1+Voorblad!$K$44)^Voorblad!$K$37-1) -> 54.376568 | AE39: =IF($W39=AE$30,EF39*($Q39*$S39)/(1+Voorblad!$K$44)^(AE$30-Voorblad!$F$37),0) -> 0 | AF39: =IF($W39=AF$30,EG39*($Q39*$S39)/(1+Voorblad!$K$44)^(AF$30-Voorblad!$F$37),0) -> 0 | AG39: =IF($W39=AG$30,EH39*($Q39*$S39)/(1+Voorblad!$K$44)^(AG$30-Voorblad!$F$37),0) -> 475.9072 | AH39: =IF($W39=AH$30,EI39*($Q39*$S39)/(1+Voorblad!$K$44)^(AH$30-Voorblad!$F$37),0) -> 0 | AI39: =IF($W39=AI$30,EJ39*($Q39*$S39)/(1+Voorblad!$K$44)^(AI$30-Voorblad!$F$37),0) -> 0 | AJ39: =IF($W39=AJ$30,EK39*($Q39*$S39)/(1+Voorblad!$K$44)^(AJ$30-Voorblad!$F$37),0) -> 0 | AK39: =IF($W39=AK$30,EL39*($Q39*$S39)/(1+Voorblad!$K$44)^(AK$30-Voorblad!$F$37),0) -> 0 | AL39: =IF($W39=AL$30,EM39*($Q39*$S39)/(1+Voorblad!$K$44)^(AL$30-Voorblad!$F$37),0) -> 0 | ... EB39: =IF($W39=EB$30,IC39*($Q39*$S39)/(1+Voorblad!$K$44)^(EB$30-Voorblad!$F$37),0) -> 0 | EE39: 0 | EF39: =IF(EF$30-Voorblad!$F$37>Voorblad!$K$37,0,IF($U39=0,0,IF($U39<1,1/$U39,IF((EF$30-Voorblad!$F$37)/$U39-SUM($EE39:EE39)=1,1,0)))) -> 0 | EG39: =IF(EG$30-Voorblad!$F$37>Voorblad!$K$37,0,IF($U39=0,0,IF($U39<1,1/$U39,IF((EG$30-Voorblad!$F$37)/$U39-SUM($EE39:EF39)=1,1,0)))) -> 1 | EH39: =IF(EH$30-Voorblad!$F$37>Voorblad!$K$37,0,IF($U39=0,0,IF($U39<1,1/$U39,IF((EH$30-Voorblad!$F$37)/$U39-SUM($EE39:EG39)=1,1,0)))) -> 1 | EI39: =IF(EI$30-Voorblad!$F$37>Voorblad!$K$37,0,IF($U39=0,0,IF($U39<1,1/$U39,IF((EI$30-Voorblad!$F$37)/$U39-SUM($EE39:EH39)=1,1,0)))) -> 1 | EJ39: =IF(EJ$30-Voorblad!$F$37>Voorblad!$K$37,0,IF($U39=0,0,IF($U39<1,1/$U39,IF((EJ$30-Voorblad!$F$37)/$U39-SUM($EE39:EI39)=1,1,0)))) -> 1 | EK39: =IF(EK$30-Voorblad!$F$37>Voorblad!$K$37,0,IF($U39=0,0,IF($U39<1,1/$U39,IF((EK$30-Voorblad!$F$37)/$U39-SUM($EE39:EJ39)=1,1,0)))) -> 1 | EL39: =IF(EL$30-Voorblad!$F$37>Voorblad!$K$37,0,IF($U39=0,0,IF($U39<1,1/$U39,IF((EL$30-Voorblad!$F$37)/$U39-SUM($EE39:EK39)=1,1,0)))) -> 1 | EM39: =IF(EM$30-Voorblad!$F$37>Voorblad!$K$37,0,IF($U39=0,0,IF($U39<1,1/$U39,IF((EM$30-Voorblad!$F$37)/$U39-SUM($EE39:EL39)=1,1,0)))) -> 1 | ... IB39: =IF(IB$30-Voorblad!$F$37>Voorblad!$K$37,0,IF($U39=0,0,IF($U39<1,1/$U39,IF((IB$30-Voorblad!$F$37)/$U39-SUM($EE39:IA39)=1,1,0)))) -> 0
B40: 2 | C40: ja | D40: 3 | E40: nee | F40: verlagen risicoprofiel | I40: insp | K40: uitvoeren nadere inspectie gehele constructie conform B2 CUR 117 | Q40: 1 | R40: post | S40: 5000 | T40: =Q40*S40 -> 5000 | U40: 1 | W40: =Voorblad!K53 -> 2020 | Y40: =SUM(AE40:EB40) -> 4759.072 | AC40: =$Y40*(Voorblad!$K$44*(1+Voorblad!$K$44)^Voorblad!$K$37)/((1+Voorblad!$K$44)^Voorblad!$K$37-1) -> 543.76568 | AE40: =IF($W40=AE$30,EF40*($Q40*$S40)/(1+Voorblad!$K$44)^(AE$30-Voorblad!$F$37),0) -> 0 | AF40: =IF($W40=AF$30,EG40*($Q40*$S40)/(1+Voorblad!$K$44)^(AF$30-Voorblad!$F$37),0) -> 0 | AG40: =IF($W40=AG$30,EH40*($Q40*$S40)/(1+Voorblad!$K$44)^(AG$30-Voorblad!$F$37),0) -> 4759.072 | AH40: =IF($W40=AH$30,EI40*($Q40*$S40)/(1+Voorblad!$K$44)^(AH$30-Voorblad!$F$37),0) -> 0 | AI40: =IF($W40=AI$30,EJ40*($Q40*$S40)/(1+Voorblad!$K$44)^(AI$30-Voorblad!$F$37),0) -> 0 | AJ40: =IF($W40=AJ$30,EK40*($Q40*$S40)/(1+Voorblad!$K$44)^(AJ$30-Voorblad!$F$37),0) -> 0 | AK40: =IF($W40=AK$30,EL40*($Q40*$S40)/(1+Voorblad!$K$44)^(AK$30-Voorblad!$F$37),0) -> 0 | AL40: =IF($W40=AL$30,EM40*($Q40*$S40)/(1+Voorblad!$K$44)^(AL$30-Voorblad!$F$37),0) -> 0 | ... EB40: =IF($W40=EB$30,IC40*($Q40*$S40)/(1+Voorblad!$K$44)^(EB$30-Voorblad!$F$37),0) -> 0 | EE40: 0 | EF40: =IF(EF$30-Voorblad!$F$37>Voorblad!$K$37,0,IF($U40=0,0,IF($U40<1,1/$U40,IF((EF$30-Voorblad!$F$37)/$U40-SUM($EE40:EE40)=1,1,0)))) -> 0 | EG40: =IF(EG$30-Voorblad!$F$37>Voorblad!$K$37,0,IF($U40=0,0,IF($U40<1,1/$U40,IF((EG$30-Voorblad!$F$37)/$U40-SUM($EE40:EF40)=1,1,0)))) -> 1 | EH40: =IF(EH$30-Voorblad!$F$37>Voorblad!$K$37,0,IF($U40=0,0,IF($U40<1,1/$U40,IF((EH$30-Voorblad!$F$37)/$U40-SUM($EE40:EG40)=1,1,0)))) -> 1 | EI40: =IF(EI$30-Voorblad!$F$37>Voorblad!$K$37,0,IF($U40=0,0,IF($U40<1,1/$U40,IF((EI$30-Voorblad!$F$37)/$U40-SUM($EE40:EH40)=1,1,0)))) -> 1 | EJ40: =IF(EJ$30-Voorblad!$F$37>Voorblad!$K$37,0,IF($U40=0,0,IF($U40<1,1/$U40,IF((EJ$30-Voorblad!$F$37)/$U40-SUM($EE40:EI40)=1,1,0)))) -> 1 | EK40: =IF(EK$30-Voorblad!$F$37>Voorblad!$K$37,0,IF($U40=0,0,IF($U40<1,1/$U40,IF((EK$30-Voorblad!$F$37)/$U40-SUM($EE40:EJ40)=1,1,0)))) -> 1 | EL40: =IF(EL$30-Voorblad!$F$37>Voorblad!$K$37,0,IF($U40=0,0,IF($U40<1,1/$U40,IF((EL$30-Voorblad!$F$37)/$U40-SUM($EE40:EK40)=1,1,0)))) -> 1 | EM40: =IF(EM$30-Voorblad!$F$37>Voorblad!$K$37,0,IF($U40=0,0,IF($U40<1,1/$U40,IF((EM$30-Voorblad!$F$37)/$U40-SUM($EE40:EL40)=1,1,0)))) -> 1 | ... IB40: =IF(IB$30-Voorblad!$F$37>Voorblad!$K$37,0,IF($U40=0,0,IF($U40<1,1/$U40,IF((IB$30-Voorblad!$F$37)/$U40-SUM($EE40:IA40)=1,1,0)))) -> 0
D41: 4 | Q41: 1 | R41: post | T41: =Q41*S41 -> 0 | U41: 1 | W41: =Voorblad!K54 -> 0 | Y41: =SUM(AE41:EB41) -> 0 | AC41: =$Y41*(Voorblad!$K$44*(1+Voorblad!$K$44)^Voorblad!$K$37)/((1+Voorblad!$K$44)^Voorblad!$K$37-1) -> 0 | AE41: =IF($W41=AE$30,EF41*($Q41*$S41)/(1+Voorblad!$K$44)^(AE$30-Voorblad!$F$37),0) -> 0 | AF41: =IF($W41=AF$30,EG41*($Q41*$S41)/(1+Voorblad!$K$44)^(AF$30-Voorblad!$F$37),0) -> 0 | AG41: =IF($W41=AG$30,EH41*($Q41*$S41)/(1+Voorblad!$K$44)^(AG$30-Voorblad!$F$37),0) -> 0 | AH41: =IF($W41=AH$30,EI41*($Q41*$S41)/(1+Voorblad!$K$44)^(AH$30-Voorblad!$F$37),0) -> 0 | AI41: =IF($W41=AI$30,EJ41*($Q41*$S41)/(1+Voorblad!$K$44)^(AI$30-Voorblad!$F$37),0) -> 0 | AJ41: =IF($W41=AJ$30,EK41*($Q41*$S41)/(1+Voorblad!$K$44)^(AJ$30-Voorblad!$F$37),0) -> 0 | AK41: =IF($W41=AK$30,EL41*($Q41*$S41)/(1+Voorblad!$K$44)^(AK$30-Voorblad!$F$37),0) -> 0 | AL41: =IF($W41=AL$30,EM41*($Q41*$S41)/(1+Voorblad!$K$44)^(AL$30-Voorblad!$F$37),0) -> 0 | ... EB41: =IF($W41=EB$30,IC41*($Q41*$S41)/(1+Voorblad!$K$44)^(EB$30-Voorblad!$F$37),0) -> 0 | EE41: 0 | EF41: =IF(EF$30-Voorblad!$F$37>Voorblad!$K$37,0,IF($U41=0,0,IF($U41<1,1/$U41,IF((EF$30-Voorblad!$F$37)/$U41-SUM($EE41:EE41)=1,1,0)))) -> 0 | EG41: =IF(EG$30-Voorblad!$F$37>Voorblad!$K$37,0,IF($U41=0,0,IF($U41<1,1/$U41,IF((EG$30-Voorblad!$F$37)/$U41-SUM($EE41:EF41)=1,1,0)))) -> 1 | EH41: =IF(EH$30-Voorblad!$F$37>Voorblad!$K$37,0,IF($U41=0,0,IF($U41<1,1/$U41,IF((EH$30-Voorblad!$F$37)/$U41-SUM($EE41:EG41)=1,1,0)))) -> 1 | EI41: =IF(EI$30-Voorblad!$F$37>Voorblad!$K$37,0,IF($U41=0,0,IF($U41<1,1/$U41,IF((EI$30-Voorblad!$F$37)/$U41-SUM($EE41:EH41)=1,1,0)))) -> 1 | EJ41: =IF(EJ$30-Voorblad!$F$37>Voorblad!$K$37,0,IF($U41=0,0,IF($U41<1,1/$U41,IF((EJ$30-Voorblad!$F$37)/$U41-SUM($EE41:EI41)=1,1,0)))) -> 1 | EK41: =IF(EK$30-Voorblad!$F$37>Voorblad!$K$37,0,IF($U41=0,0,IF($U41<1,1/$U41,IF((EK$30-Voorblad!$F$37)/$U41-SUM($EE41:EJ41)=1,1,0)))) -> 1 | EL41: =IF(EL$30-Voorblad!$F$37>Voorblad!$K$37,0,IF($U41=0,0,IF($U41<1,1/$U41,IF((EL$30-Voorblad!$F$37)/$U41-SUM($EE41:EK41)=1,1,0)))) -> 1 | EM41: =IF(EM$30-Voorblad!$F$37>Voorblad!$K$37,0,IF($U41=0,0,IF($U41<1,1/$U41,IF((EM$30-Voorblad!$F$37)/$U41-SUM($EE41:EL41)=1,1,0)))) -> 1 | ... IB41: =IF(IB$30-Voorblad!$F$37>Voorblad!$K$37,0,IF($U41=0,0,IF($U41<1,1/$U41,IF((IB$30-Voorblad!$F$37)/$U41-SUM($EE41:IA41)=1,1,0)))) -> 0
D42: 5 | Q42: 1 | R42: post | T42: =Q42*S42 -> 0 | U42: 1 | W42: =Voorblad!K55 -> 0 | Y42: =SUM(AE42:EB42) -> 0 | AC42: =$Y42*(Voorblad!$K$44*(1+Voorblad!$K$44)^Voorblad!$K$37)/((1+Voorblad!$K$44)^Voorblad!$K$37-1) -> 0 | AE42: =IF($W42=AE$30,EF42*($Q42*$S42)/(1+Voorblad!$K$44)^(AE$30-Voorblad!$F$37),0) -> 0 | AF42: =IF($W42=AF$30,EG42*($Q42*$S42)/(1+Voorblad!$K$44)^(AF$30-Voorblad!$F$37),0) -> 0 | AG42: =IF($W42=AG$30,EH42*($Q42*$S42)/(1+Voorblad!$K$44)^(AG$30-Voorblad!$F$37),0) -> 0 | AH42: =IF($W42=AH$30,EI42*($Q42*$S42)/(1+Voorblad!$K$44)^(AH$30-Voorblad!$F$37),0) -> 0 | AI42: =IF($W42=AI$30,EJ42*($Q42*$S42)/(1+Voorblad!$K$44)^(AI$30-Voorblad!$F$37),0) -> 0 | AJ42: =IF($W42=AJ$30,EK42*($Q42*$S42)/(1+Voorblad!$K$44)^(AJ$30-Voorblad!$F$37),0) -> 0 | AK42: =IF($W42=AK$30,EL42*($Q42*$S42)/(1+Voorblad!$K$44)^(AK$30-Voorblad!$F$37),0) -> 0 | AL42: =IF($W42=AL$30,EM42*($Q42*$S42)/(1+Voorblad!$K$44)^(AL$30-Voorblad!$F$37),0) -> 0 | ... EB42: =IF($W42=EB$30,IC42*($Q42*$S42)/(1+Voorblad!$K$44)^(EB$30-Voorblad!$F$37),0) -> 0 | EE42: 0 | EF42: =IF(EF$30-Voorblad!$F$37>Voorblad!$K$37,0,IF($U42=0,0,IF($U42<1,1/$U42,IF((EF$30-Voorblad!$F$37)/$U42-SUM($EE42:EE42)=1,1,0)))) -> 0 | EG42: =IF(EG$30-Voorblad!$F$37>Voorblad!$K$37,0,IF($U42=0,0,IF($U42<1,1/$U42,IF((EG$30-Voorblad!$F$37)/$U42-SUM($EE42:EF42)=1,1,0)))) -> 1 | EH42: =IF(EH$30-Voorblad!$F$37>Voorblad!$K$37,0,IF($U42=0,0,IF($U42<1,1/$U42,IF((EH$30-Voorblad!$F$37)/$U42-SUM($EE42:EG42)=1,1,0)))) -> 1 | EI42: =IF(EI$30-Voorblad!$F$37>Voorblad!$K$37,0,IF($U42=0,0,IF($U42<1,1/$U42,IF((EI$30-Voorblad!$F$37)/$U42-SUM($EE42:EH42)=1,1,0)))) -> 1 | EJ42: =IF(EJ$30-Voorblad!$F$37>Voorblad!$K$37,0,IF($U42=0,0,IF($U42<1,1/$U42,IF((EJ$30-Voorblad!$F$37)/$U42-SUM($EE42:EI42)=1,1,0)))) -> 1 | EK42: =IF(EK$30-Voorblad!$F$37>Voorblad!$K$37,0,IF($U42=0,0,IF($U42<1,1/$U42,IF((EK$30-Voorblad!$F$37)/$U42-SUM($EE42:EJ42)=1,1,0)))) -> 1 | EL42: =IF(EL$30-Voorblad!$F$37>Voorblad!$K$37,0,IF($U42=0,0,IF($U42<1,1/$U42,IF((EL$30-Voorblad!$F$37)/$U42-SUM($EE42:EK42)=1,1,0)))) -> 1 | EM42: =IF(EM$30-Voorblad!$F$37>Voorblad!$K$37,0,IF($U42=0,0,IF($U42<1,1/$U42,IF((EM$30-Voorblad!$F$37)/$U42-SUM($EE42:EL42)=1,1,0)))) -> 1 | ... IB42: =IF(IB$30-Voorblad!$F$37>Voorblad!$K$37,0,IF($U42=0,0,IF($U42<1,1/$U42,IF((IB$30-Voorblad!$F$37)/$U42-SUM($EE42:IA42)=1,1,0)))) -> 0
D43: 6 | Q43: 1 | R43: post | T43: =Q43*S43 -> 0 | U43: 1 | W43: =Voorblad!K56 -> 0 | Y43: =SUM(AE43:EB43) -> 0 | AC43: =$Y43*(Voorblad!$K$44*(1+Voorblad!$K$44)^Voorblad!$K$37)/((1+Voorblad!$K$44)^Voorblad!$K$37-1) -> 0 | AE43: =IF($W43=AE$30,EF43*($Q43*$S43)/(1+Voorblad!$K$44)^(AE$30-Voorblad!$F$37),0) -> 0 | AF43: =IF($W43=AF$30,EG43*($Q43*$S43)/(1+Voorblad!$K$44)^(AF$30-Voorblad!$F$37),0) -> 0 | AG43: =IF($W43=AG$30,EH43*($Q43*$S43)/(1+Voorblad!$K$44)^(AG$30-Voorblad!$F$37),0) -> 0 | AH43: =IF($W43=AH$30,EI43*($Q43*$S43)/(1+Voorblad!$K$44)^(AH$30-Voorblad!$F$37),0) -> 0 | AI43: =IF($W43=AI$30,EJ43*($Q43*$S43)/(1+Voorblad!$K$44)^(AI$30-Voorblad!$F$37),0) -> 0 | AJ43: =IF($W43=AJ$30,EK43*($Q43*$S43)/(1+Voorblad!$K$44)^(AJ$30-Voorblad!$F$37),0) -> 0 | AK43: =IF($W43=AK$30,EL43*($Q43*$S43)/(1+Voorblad!$K$44)^(AK$30-Voorblad!$F$37),0) -> 0 | AL43: =IF($W43=AL$30,EM43*($Q43*$S43)/(1+Voorblad!$K$44)^(AL$30-Voorblad!$F$37),0) -> 0 | ... EB43: =IF($W43=EB$30,IC43*($Q43*$S43)/(1+Voorblad!$K$44)^(EB$30-Voorblad!$F$37),0) -> 0 | EE43: 0 | EF43: =IF(EF$30-Voorblad!$F$37>Voorblad!$K$37,0,IF($U43=0,0,IF($U43<1,1/$U43,IF((EF$30-Voorblad!$F$37)/$U43-SUM($EE43:EE43)=1,1,0)))) -> 0 | EG43: =IF(EG$30-Voorblad!$F$37>Voorblad!$K$37,0,IF($U43=0,0,IF($U43<1,1/$U43,IF((EG$30-Voorblad!$F$37)/$U43-SUM($EE43:EF43)=1,1,0)))) -> 1 | EH43: =IF(EH$30-Voorblad!$F$37>Voorblad!$K$37,0,IF($U43=0,0,IF($U43<1,1/$U43,IF((EH$30-Voorblad!$F$37)/$U43-SUM($EE43:EG43)=1,1,0)))) -> 1 | EI43: =IF(EI$30-Voorblad!$F$37>Voorblad!$K$37,0,IF($U43=0,0,IF($U43<1,1/$U43,IF((EI$30-Voorblad!$F$37)/$U43-SUM($EE43:EH43)=1,1,0)))) -> 1 | EJ43: =IF(EJ$30-Voorblad!$F$37>Voorblad!$K$37,0,IF($U43=0,0,IF($U43<1,1/$U43,IF((EJ$30-Voorblad!$F$37)/$U43-SUM($EE43:EI43)=1,1,0)))) -> 1 | EK43: =IF(EK$30-Voorblad!$F$37>Voorblad!$K$37,0,IF($U43=0,0,IF($U43<1,1/$U43,IF((EK$30-Voorblad!$F$37)/$U43-SUM($EE43:EJ43)=1,1,0)))) -> 1 | EL43: =IF(EL$30-Voorblad!$F$37>Voorblad!$K$37,0,IF($U43=0,0,IF($U43<1,1/$U43,IF((EL$30-Voorblad!$F$37)/$U43-SUM($EE43:EK43)=1,1,0)))) -> 1 | EM43: =IF(EM$30-Voorblad!$F$37>Voorblad!$K$37,0,IF($U43=0,0,IF($U43<1,1/$U43,IF((EM$30-Voorblad!$F$37)/$U43-SUM($EE43:EL43)=1,1,0)))) -> 1 | ... IB43: =IF(IB$30-Voorblad!$F$37>Voorblad!$K$37,0,IF($U43=0,0,IF($U43<1,1/$U43,IF((IB$30-Voorblad!$F$37)/$U43-SUM($EE43:IA43)=1,1,0)))) -> 0
D44: 7 | Q44: 1 | R44: post | T44: =Q44*S44 -> 0 | U44: 1 | W44: =Voorblad!K57 -> 0 | Y44: =SUM(AE44:EB44) -> 0 | AC44: =$Y44*(Voorblad!$K$44*(1+Voorblad!$K$44)^Voorblad!$K$37)/((1+Voorblad!$K$44)^Voorblad!$K$37-1) -> 0 | AE44: =IF($W44=AE$30,EF44*($Q44*$S44)/(1+Voorblad!$K$44)^(AE$30-Voorblad!$F$37),0) -> 0 | AF44: =IF($W44=AF$30,EG44*($Q44*$S44)/(1+Voorblad!$K$44)^(AF$30-Voorblad!$F$37),0) -> 0 | AG44: =IF($W44=AG$30,EH44*($Q44*$S44)/(1+Voorblad!$K$44)^(AG$30-Voorblad!$F$37),0) -> 0 | AH44: =IF($W44=AH$30,EI44*($Q44*$S44)/(1+Voorblad!$K$44)^(AH$30-Voorblad!$F$37),0) -> 0 | AI44: =IF($W44=AI$30,EJ44*($Q44*$S44)/(1+Voorblad!$K$44)^(AI$30-Voorblad!$F$37),0) -> 0 | AJ44: =IF($W44=AJ$30,EK44*($Q44*$S44)/(1+Voorblad!$K$44)^(AJ$30-Voorblad!$F$37),0) -> 0 | AK44: =IF($W44=AK$30,EL44*($Q44*$S44)/(1+Voorblad!$K$44)^(AK$30-Voorblad!$F$37),0) -> 0 | AL44: =IF($W44=AL$30,EM44*($Q44*$S44)/(1+Voorblad!$K$44)^(AL$30-Voorblad!$F$37),0) -> 0 | ... EB44: =IF($W44=EB$30,IC44*($Q44*$S44)/(1+Voorblad!$K$44)^(EB$30-Voorblad!$F$37),0) -> 0 | EE44: 0 | EF44: =IF(EF$30-Voorblad!$F$37>Voorblad!$K$37,0,IF($U44=0,0,IF($U44<1,1/$U44,IF((EF$30-Voorblad!$F$37)/$U44-SUM($EE44:EE44)=1,1,0)))) -> 0 | EG44: =IF(EG$30-Voorblad!$F$37>Voorblad!$K$37,0,IF($U44=0,0,IF($U44<1,1/$U44,IF((EG$30-Voorblad!$F$37)/$U44-SUM($EE44:EF44)=1,1,0)))) -> 1 | EH44: =IF(EH$30-Voorblad!$F$37>Voorblad!$K$37,0,IF($U44=0,0,IF($U44<1,1/$U44,IF((EH$30-Voorblad!$F$37)/$U44-SUM($EE44:EG44)=1,1,0)))) -> 1 | EI44: =IF(EI$30-Voorblad!$F$37>Voorblad!$K$37,0,IF($U44=0,0,IF($U44<1,1/$U44,IF((EI$30-Voorblad!$F$37)/$U44-SUM($EE44:EH44)=1,1,0)))) -> 1 | EJ44: =IF(EJ$30-Voorblad!$F$37>Voorblad!$K$37,0,IF($U44=0,0,IF($U44<1,1/$U44,IF((EJ$30-Voorblad!$F$37)/$U44-SUM($EE44:EI44)=1,1,0)))) -> 1 | EK44: =IF(EK$30-Voorblad!$F$37>Voorblad!$K$37,0,IF($U44=0,0,IF($U44<1,1/$U44,IF((EK$30-Voorblad!$F$37)/$U44-SUM($EE44:EJ44)=1,1,0)))) -> 1 | EL44: =IF(EL$30-Voorblad!$F$37>Voorblad!$K$37,0,IF($U44=0,0,IF($U44<1,1/$U44,IF((EL$30-Voorblad!$F$37)/$U44-SUM($EE44:EK44)=1,1,0)))) -> 1 | EM44: =IF(EM$30-Voorblad!$F$37>Voorblad!$K$37,0,IF($U44=0,0,IF($U44<1,1/$U44,IF((EM$30-Voorblad!$F$37)/$U44-SUM($EE44:EL44)=1,1,0)))) -> 1 | ... IB44: =IF(IB$30-Voorblad!$F$37>Voorblad!$K$37,0,IF($U44=0,0,IF($U44<1,1/$U44,IF((IB$30-Voorblad!$F$37)/$U44-SUM($EE44:IA44)=1,1,0)))) -> 0
D45: 8 | Q45: 1 | R45: post | T45: =Q45*S45 -> 0 | U45: 1 | W45: =Voorblad!K58 -> 0 | Y45: =SUM(AE45:EB45) -> 0 | AC45: =$Y45*(Voorblad!$K$44*(1+Voorblad!$K$44)^Voorblad!$K$37)/((1+Voorblad!$K$44)^Voorblad!$K$37-1) -> 0 | AE45: =IF($W45=AE$30,EF45*($Q45*$S45)/(1+Voorblad!$K$44)^(AE$30-Voorblad!$F$37),0) -> 0 | AF45: =IF($W45=AF$30,EG45*($Q45*$S45)/(1+Voorblad!$K$44)^(AF$30-Voorblad!$F$37),0) -> 0 | AG45: =IF($W45=AG$30,EH45*($Q45*$S45)/(1+Voorblad!$K$44)^(AG$30-Voorblad!$F$37),0) -> 0 | AH45: =IF($W45=AH$30,EI45*($Q45*$S45)/(1+Voorblad!$K$44)^(AH$30-Voorblad!$F$37),0) -> 0 | AI45: =IF($W45=AI$30,EJ45*($Q45*$S45)/(1+Voorblad!$K$44)^(AI$30-Voorblad!$F$37),0) -> 0 | AJ45: =IF($W45=AJ$30,EK45*($Q45*$S45)/(1+Voorblad!$K$44)^(AJ$30-Voorblad!$F$37),0) -> 0 | AK45: =IF($W45=AK$30,EL45*($Q45*$S45)/(1+Voorblad!$K$44)^(AK$30-Voorblad!$F$37),0) -> 0 | AL45: =IF($W45=AL$30,EM45*($Q45*$S45)/(1+Voorblad!$K$44)^(AL$30-Voorblad!$F$37),0) -> 0 | ... EB45: =IF($W45=EB$30,IC45*($Q45*$S45)/(1+Voorblad!$K$44)^(EB$30-Voorblad!$F$37),0) -> 0 | EE45: 0 | EF45: =IF(EF$30-Voorblad!$F$37>Voorblad!$K$37,0,IF($U45=0,0,IF($U45<1,1/$U45,IF((EF$30-Voorblad!$F$37)/$U45-SUM($EE45:EE45)=1,1,0)))) -> 0 | EG45: =IF(EG$30-Voorblad!$F$37>Voorblad!$K$37,0,IF($U45=0,0,IF($U45<1,1/$U45,IF((EG$30-Voorblad!$F$37)/$U45-SUM($EE45:EF45)=1,1,0)))) -> 1 | EH45: =IF(EH$30-Voorblad!$F$37>Voorblad!$K$37,0,IF($U45=0,0,IF($U45<1,1/$U45,IF((EH$30-Voorblad!$F$37)/$U45-SUM($EE45:EG45)=1,1,0)))) -> 1 | EI45: =IF(EI$30-Voorblad!$F$37>Voorblad!$K$37,0,IF($U45=0,0,IF($U45<1,1/$U45,IF((EI$30-Voorblad!$F$37)/$U45-SUM($EE45:EH45)=1,1,0)))) -> 1 | EJ45: =IF(EJ$30-Voorblad!$F$37>Voorblad!$K$37,0,IF($U45=0,0,IF($U45<1,1/$U45,IF((EJ$30-Voorblad!$F$37)/$U45-SUM($EE45:EI45)=1,1,0)))) -> 1 | EK45: =IF(EK$30-Voorblad!$F$37>Voorblad!$K$37,0,IF($U45=0,0,IF($U45<1,1/$U45,IF((EK$30-Voorblad!$F$37)/$U45-SUM($EE45:EJ45)=1,1,0)))) -> 1 | EL45: =IF(EL$30-Voorblad!$F$37>Voorblad!$K$37,0,IF($U45=0,0,IF($U45<1,1/$U45,IF((EL$30-Voorblad!$F$37)/$U45-SUM($EE45:EK45)=1,1,0)))) -> 1 | EM45: =IF(EM$30-Voorblad!$F$37>Voorblad!$K$37,0,IF($U45=0,0,IF($U45<1,1/$U45,IF((EM$30-Voorblad!$F$37)/$U45-SUM($EE45:EL45)=1,1,0)))) -> 1 | ... IB45: =IF(IB$30-Voorblad!$F$37>Voorblad!$K$37,0,IF($U45=0,0,IF($U45<1,1/$U45,IF((IB$30-Voorblad!$F$37)/$U45-SUM($EE45:IA45)=1,1,0)))) -> 0
B46: 1 | C46: nee | D46: nvt | E46: nvt | F46: einde levensduur | I46: vv | K46: vervangingskosten (incl. sloop bestaand) | O46: bij PER DIRECTE vervanging komen de BHM te vervallen | P46: vervanging gehele duiker BxL | Q46: =11*(1.7+8+1.7) -> 125.4 | R46: m2 | S46: 8500 | T46: =Q46*S46 -> 1065900 | U46: 1 | V46: =Voorblad!F24+100 -> 2053 | W46: =Voorblad!K59 -> 2053 | Y46: =SUM(AE46:EB46) -> 0 | Z46: 2x52 | AA46: =2*52 -> 104 | AC46: =$Y46*(Voorblad!$K$44*(1+Voorblad!$K$44)^Voorblad!$K$37)/((1+Voorblad!$K$44)^Voorblad!$K$37-1) -> 0 | AE46: =IF($W46=AE$30,EF46*($Q46*$S46)/(1+Voorblad!$K$44)^(AE$30-Voorblad!$F$37),0) -> 0 | AF46: =IF($W46=AF$30,EG46*($Q46*$S46)/(1+Voorblad!$K$44)^(AF$30-Voorblad!$F$37),0) -> 0 | AG46: =IF($W46=AG$30,EH46*($Q46*$S46)/(1+Voorblad!$K$44)^(AG$30-Voorblad!$F$37),0) -> 0 | AH46: =IF($W46=AH$30,EI46*($Q46*$S46)/(1+Voorblad!$K$44)^(AH$30-Voorblad!$F$37),0) -> 0 | AI46: =IF($W46=AI$30,EJ46*($Q46*$S46)/(1+Voorblad!$K$44)^(AI$30-Voorblad!$F$37),0) -> 0 | AJ46: =IF($W46=AJ$30,EK46*($Q46*$S46)/(1+Voorblad!$K$44)^(AJ$30-Voorblad!$F$37),0) -> 0 | AK46: =IF($W46=AK$30,EL46*($Q46*$S46)/(1+Voorblad!$K$44)^(AK$30-Voorblad!$F$37),0) -> 0 | AL46: =IF($W46=AL$30,EM46*($Q46*$S46)/(1+Voorblad!$K$44)^(AL$30-Voorblad!$F$37),0) -> 0 | ... EB46: =IF($W46=EB$30,IC46*($Q46*$S46)/(1+Voorblad!$K$44)^(EB$30-Voorblad!$F$37),0) -> 0 | EE46: 0 | EF46: =IF(EF$30-Voorblad!$F$37>Voorblad!$K$37,0,IF($U46=0,0,IF($U46<1,1/$U46,IF((EF$30-Voorblad!$F$37)/$U46-SUM($EE46:EE46)=1,1,0)))) -> 0 | EG46: =IF(EG$30-Voorblad!$F$37>Voorblad!$K$37,0,IF($U46=0,0,IF($U46<1,1/$U46,IF((EG$30-Voorblad!$F$37)/$U46-SUM($EE46:EF46)=1,1,0)))) -> 1 | EH46: =IF(EH$30-Voorblad!$F$37>Voorblad!$K$37,0,IF($U46=0,0,IF($U46<1,1/$U46,IF((EH$30-Voorblad!$F$37)/$U46-SUM($EE46:EG46)=1,1,0)))) -> 1 | EI46: =IF(EI$30-Voorblad!$F$37>Voorblad!$K$37,0,IF($U46=0,0,IF($U46<1,1/$U46,IF((EI$30-Voorblad!$F$37)/$U46-SUM($EE46:EH46)=1,1,0)))) -> 1 | EJ46: =IF(EJ$30-Voorblad!$F$37>Voorblad!$K$37,0,IF($U46=0,0,IF($U46<1,1/$U46,IF((EJ$30-Voorblad!$F$37)/$U46-SUM($EE46:EI46)=1,1,0)))) -> 1 | EK46: =IF(EK$30-Voorblad!$F$37>Voorblad!$K$37,0,IF($U46=0,0,IF($U46<1,1/$U46,IF((EK$30-Voorblad!$F$37)/$U46-SUM($EE46:EJ46)=1,1,0)))) -> 1 | EL46: =IF(EL$30-Voorblad!$F$37>Voorblad!$K$37,0,IF($U46=0,0,IF($U46<1,1/$U46,IF((EL$30-Voorblad!$F$37)/$U46-SUM($EE46:EK46)=1,1,0)))) -> 1 | EM46: =IF(EM$30-Voorblad!$F$37>Voorblad!$K$37,0,IF($U46=0,0,IF($U46<1,1/$U46,IF((EM$30-Voorblad!$F$37)/$U46-SUM($EE46:EL46)=1,1,0)))) -> 1 | ... IB46: =IF(IB$30-Voorblad!$F$37>Voorblad!$K$37,0,IF($U46=0,0,IF($U46<1,1/$U46,IF((IB$30-Voorblad!$F$37)/$U46-SUM($EE46:IA46)=1,1,0)))) -> 0
B47: totaal beheersmaatregelen
B50: LANGETERMIJNPLAN (LTP)
B52: Maak keuze uit één van de onderstaande type kunstwerk en type onderbouw
B54: Kosten | F54: Thema | I54: Maat- | K54: Omschrijving | O54: Uitgangspunten | P54: Aanvullende informatie | Q54: hoev | R54: eenh. | S54: eenh.prijs | T54: kosten | U54: freq | V54: theor.einde | W54: uitvoering | Y54: Σ NCW | Z54: TVP | AA54: TVP duur | AC54: Equiv. | AE54: (Netto Contante) Waarde tabel | EE54: Onderwaterscherm wel/geen waarde
B55: cat. | I55: regel | V55: levensd | AC55: jaarlast
...
